<?xml version="1.0" ?>
<sdf version='1.6'>
  <model name='edo_gripper'>
    <static>false</static>
    <link name='base_link'>
      <pose frame=''>0 0 0 0 -0 0</pose>
      <inertial>
        <pose frame=''>0 0 0 0 -0 0</pose>
        <mass>0.05</mass>
        <inertia>
          <ixx>1</ixx>
          <ixy>0</ixy>
          <ixz>0</ixz>
          <iyy>1</iyy>
          <iyz>0</iyz>
          <izz>1</izz>
        </inertia>
      </inertial>
      <collision name='base_link_collision'>
        <pose frame=''>-0.035 0 -0.035 0 -0 0</pose>
        <geometry>
          <mesh>
            <scale>1 1 1</scale>
            <uri>model://edo_gripper/meshes/base.STL</uri>
          </mesh>
        </geometry>
      </collision>
      <visual name='base_link_visual'>
        <pose frame=''>-0.035 0 -0.035 0 -0 0</pose>
        <geometry>
          <mesh>
            <scale>1 1 1</scale>
            <uri>model://edo_gripper/meshes/base.STL</uri>
          </mesh>
        </geometry>
      </visual>
    </link>
    <link name='link_finger_base_left'>
      <pose frame=''>0.025 0.0195 0 0 -0 0</pose>
      <inertial>
        <pose frame=''>0 0 0 0 -0 0</pose>
        <mass>0.005</mass>
        <inertia>
          <ixx>1</ixx>
          <ixy>0</ixy>
          <ixz>0</ixz>
          <iyy>1</iyy>
          <iyz>0</iyz>
          <izz>1</izz>
        </inertia>
      </inertial>
      <collision name='link_finger_base_left_collision'>
        <pose frame=''>-0.005 0 -0.04 0 -0 0</pose>
        <geometry>
          <mesh>
            <scale>1 1 1</scale>
            <uri>model://edo_gripper/meshes/finger_base.STL</uri>
          </mesh>
        </geometry>
      </collision>
      <visual name='link_finger_base_left_visual'>
        <pose frame=''>-0.005 0 -0.04 0 -0 0</pose>
        <geometry>
          <mesh>
            <scale>1 1 1</scale>
            <uri>model://edo_gripper/meshes/finger_base.STL</uri>
          </mesh>
        </geometry>
      </visual>
    </link>
    <joint name='joint_base_left' type='revolute'>
      <child>link_finger_base_left</child>
      <parent>base_link</parent>
      <axis>
        <xyz>0 0 1</xyz>
        <limit>
          <lower>-1.5708</lower>
          <upper>1.5708</upper>
          <effort>100</effort>
          <velocity>100</velocity>
        </limit>
        <dynamics>
          <spring_reference>0</spring_reference>
          <spring_stiffness>0</spring_stiffness>
        </dynamics>
        <use_parent_model_frame>1</use_parent_model_frame>
      </axis>
    </joint>
    <link name='link_finger_tip_left'>
      <pose frame=''>0.025 0.0595 0 0 -0 0</pose>
      <inertial>
        <pose frame=''>0 0 0 0 -0 0</pose>
        <mass>0.005</mass>
        <inertia>
          <ixx>1</ixx>
          <ixy>0</ixy>
          <ixz>0</ixz>
          <iyy>1</iyy>
          <iyz>0</iyz>
          <izz>1</izz>
        </inertia>
      </inertial>
      <collision name='link_finger_tip_left_collision'>
        <pose frame=''>-0.071 0 0 0 -0 0</pose>
        <geometry>
          <mesh>
            <scale>1 1 1</scale>
            <uri>model://edo_gripper/meshes/finger_tip.STL</uri>
          </mesh>
        </geometry>
      </collision>
      <visual name='link_finger_tip_left_visual'>
        <pose frame=''>-0.071 0 0 0 -0 0</pose>
        <geometry>
          <mesh>
            <scale>1 1 1</scale>
            <uri>model://edo_gripper/meshes/finger_tip.STL</uri>
          </mesh>
        </geometry>
      </visual>
    </link>
    <joint name='joint_finger_left' type='revolute'>
      <child>link_finger_tip_left</child>
      <parent>link_finger_base_left</parent>
      <axis>
        <xyz>0 0 1</xyz>
        <limit>
          <lower>-1.5708</lower>
          <upper>1.5708</upper>
          <effort>100</effort>
          <velocity>100</velocity>
        </limit>
        <dynamics>
          <spring_reference>0</spring_reference>
          <spring_stiffness>0</spring_stiffness>
        </dynamics>
        <use_parent_model_frame>1</use_parent_model_frame>
      </axis>
    </joint>
    <link name='link_finger_base_right'>
      <pose frame=''>-0.025 0.0195 0 3.14159 0 3.14159</pose>
      <inertial>
        <pose frame=''>0 0 0 0 -0 0</pose>
        <mass>0.005</mass>
        <inertia>
          <ixx>1</ixx>
          <ixy>0</ixy>
          <ixz>0</ixz>
          <iyy>1</iyy>
          <iyz>0</iyz>
          <izz>1</izz>
        </inertia>
      </inertial>
      <collision name='link_finger_base_right_collision'>
        <pose frame=''>-0.005 0 -0.04 0 -0 0</pose>
        <geometry>
          <mesh>
            <scale>1 1 1</scale>
            <uri>model://edo_gripper/meshes/finger_base.STL</uri>
          </mesh>
        </geometry>
      </collision>
      <visual name='link_finger_base_right_visual'>
        <pose frame=''>-0.005 0 -0.04 0 -0 0</pose>
        <geometry>
          <mesh>
            <scale>1 1 1</scale>
            <uri>model://edo_gripper/meshes/finger_base.STL</uri>
          </mesh>
        </geometry>
      </visual>
    </link>
    <joint name='joint_base_right' type='revolute'>
      <child>link_finger_base_right</child>
      <parent>base_link</parent>
      <axis>
        <xyz>0 0 -1</xyz>
        <limit>
          <lower>-1.5708</lower>
          <upper>1.5708</upper>
          <effort>100</effort>
          <velocity>100</velocity>
        </limit>
        <dynamics>
          <spring_reference>0</spring_reference>
          <spring_stiffness>0</spring_stiffness>
        </dynamics>
        <use_parent_model_frame>1</use_parent_model_frame>
      </axis>
    </joint>
    <link name='link_finger_tip_right'>
      <pose frame=''>-0.025 0.0595 0 3.14159 0 3.14159</pose>
      <inertial>
        <pose frame=''>0 0 0 0 -0 0</pose>
        <mass>0.005</mass>
        <inertia>
          <ixx>1</ixx>
          <ixy>0</ixy>
          <ixz>0</ixz>
          <iyy>1</iyy>
          <iyz>0</iyz>
          <izz>1</izz>
        </inertia>
      </inertial>
      <collision name='link_finger_tip_right_collision'>
        <pose frame=''>-0.071 0 0 0 -0 0</pose>
        <geometry>
          <mesh>
            <scale>1 1 1</scale>
            <uri>model://edo_gripper/meshes/finger_tip.STL</uri>
          </mesh>
        </geometry>
      </collision>
      <visual name='link_finger_tip_right_visual'>
        <pose frame=''>-0.071 0 0 0 -0 0</pose>
        <geometry>
          <mesh>
            <scale>1 1 1</scale>
            <uri>model://edo_gripper/meshes/finger_tip.STL</uri>
          </mesh>
        </geometry>
      </visual>
    </link>
    <joint name='joint_finger_right' type='revolute'>
      <child>link_finger_tip_right</child>
      <parent>link_finger_base_right</parent>
      <axis>
        <xyz>0 0 -1</xyz>
        <limit>
          <lower>-1.5708</lower>
          <upper>1.5708</upper>
          <effort>100</effort>
          <velocity>100</velocity>
        </limit>
        <dynamics>
          <spring_reference>0</spring_reference>
          <spring_stiffness>0</spring_stiffness>
        </dynamics>
        <use_parent_model_frame>1</use_parent_model_frame>
      </axis>
    </joint>

    <plugin name="edo_gripper" filename="libedo_gripper.so"/>
  </model>
</sdf>
